Workbook

Sheet Form 1
A1: Form I
A2: PLOT APPROACH FORM
A3: Name of Division: | C3: Mangalore Division
A4: SI.No | B4: Heading | C4: Description
A5: 1 | B5: Range | C5: Belthangady
A6: 2 | B6: Block and/or beat | C6: Belthangady Aranya kshetra
A7: 3 | B7: Compartment | C7: II-41
A8: 4 | B8: Grid | C8: 6173B
A9: 5 | B9: Latitude | C9: 12.967142
A10: 6 | B10: Longitude | C10: 75.280134
A11: 7 | B11: Journey/approach to the plot | C11: Trvel from Ujire to Belthangady upto N 12.967610 E 75.281942 by vehicle then travel in the bearing of 250 degree upto a distance of 200 m to reach the grid.
A12: 8 | B12: Ocular stock assessment | C12: Acacia auriculiformis , Aporosa lindleyana , Xylia xylocarpa , Macaranga peltata
A13: 9 | B13: General observational information | C13: Tract - Hilly
C14: Aspect - NW
C15: Canopy Dencity - 0.35
C16: Soil - Red latterite
C17: Grasses - Arundinella sp
C18: Weeds - Chromolaena odorata ,
C19: Bamboos - Bambusa bambos
C20: Herbs - Ixora coccinia chinensis
C21: Shrubs - Ziziphus oenoplia
C22: Underwood species – Callicarpa tomentosa , Terminalia paniculata
C23: Climbers - Acacia concinna , Jasminum malabaricum
C24: Rattans – NIL
C25: NTFP yieding sps –Acacia concinna
A26: 10 | B26: Conspicuous features | C26: Enchroachment nearby
A27: 11 | B27: Removal of fuel wood and fodder | C27: Heavy
A28: 12 | B28: Refrence Tree Si No | C28: 1
A29: 13 | B29: Distance of Grid Centre from reference tree | C29: 3.5m

Sheet Form II
A1: Form II
A2: PLOT DESCRIPTION FORM
A3: Name of Division: | C3: Mangalore Division
A4: SI.No | B4: Description | C4: Remarks
A5: 1 | B5: Range | C5: ='Form 1'!C5 -> Belthangady
A6: 2 | B6: Sec & or beat
A7: 3 | B7: Block and Compartment | C7: ='Form 1'!C6 -> Belthangady Aranya kshetra
A8: 4 | B8: Grid | C8: ='Form 1'!C8 -> 6173B
A9: 5 | B9: LAT. | C9: ='Form 1'!C9 -> 12.967142
A10: 6 | B10: LONG. | C10: ='Form 1'!C10 -> 75.280134
A11: 7 | B11: ALT. | C11: 378 ft
A12: 8 | B12: Legal Status | C12: Reserve Forest / Protected Forest/ Un classed Forest /Private Forest/ Private Land
A13: 9 | B13: Land Use | C13: Closed Forest /Dense Forest /Open Forest / Scrub
A14: 10 | B14: General topography | C14: Flat / Gently rolling / Ravines / Gullies / Hilly /Very Hilly
A15: 11 | B15: Slope | C15: Upto 3° /4°-15°/ 16°-40° /41° and Above
A16: 12 | B16: Aspect | C16: Northern / NE/Eastern / SE /Southern /SW /Western/ NW /No aspect
A17: 13 | B17: Rock and geology | C17: Sedimentary Rocks / Metamorphic Rocks / Ignecious Rocks
A18: 14 | B18: Soil data | C18: Texture- Gravelly
C19: Depth- Shallow
C20: Permiability- Moderate
A21: 15 | B21: Soil erosion | C21: Heavy / Moderate /Mild /No erosion
A22: 16 | B22: Crop composition | C22: Xylia xylocarpa , Macaranga peltata , Aporosa lindleyana
A23: 17 | B23: Regeneration status(general observation) | C23: Adequate/ Moderate/ Poor /Absent
A24: 18 | B24: Injury/ damage to crop, if any | C24: Top drying / Lopping / Girdling / Scarring / Damage by natural calamities / None
A25: 19 | B25: Biotic Influence | C25: Human activities
A26: 20 | B26: Grazing incidence | C26: Heavy / Moderate / Light / None
A27: 21 | B27: Presence of bamboos | C27: Present / Absent
A28: 22 | B28: Presence of grasses | C28: Very dense / Dense / Moderate / Scanty / Absent
A29: 23 | B29: Presence of weeds | C29: Very dense / Dense / Moderate / Scanty / Absent
A30: 24 | B30: Invasive Species | C30: NIL
A31: 25 | B31: Plantation status | C31: NIL
A32: 26 | B32: water bodies | C32: NIL
... A36: 30 | B36: Canopy Density class( >0.75,0.5-0.75,<0.5) | C36: <0.5

Sheet Form No 3
A1: Field Form No.3
A2: PLOT ENUMERATION AND SAMPLE TREE FORM
A4: Job no.* | B4: Form Code* | C4: Mapsheet No.* | D4: Grid code* | F4: Sub-plot* | G4: Slope %* | H4: Sub-plot status * | I4: Land use class of Sub-plot* | J4: Sub-plot Selected for STF(Yes/No)* | L4: Total No.of bamboo clumps* | M4: Total no. of tress*
A5: 1(3) | B5: 2(2) | C5: 3(6) | D5: 4(6) | F5: 5(1) | G5: 6(3) | H5: 7(1) | I5: 7a(2) | J5: 7(b) | L5: 26(3) | M5: 27(3)
B6: 3
A8: SI NO | B8: Plot Enumeration Form Parameters | I8: Sample tree form Parameters | T8: Remarks( if any NTFP utility)
B9: Species Name* | C9: Species code * | D9: GBH (cm)* | E9: Status of tree (Dead/Alive)* | F9: Cause of death in case of mortailty* | G9: rotten/missing cull* | H9: Decay class* | I9: Crown width (meter) | K9: Height(meter) | N9: Incidence of Insect* | O9: Incidence of Disease* | P9: DBT(mm)* | Q9: Bark Void% | R9: Clearbole height(m)* | S9: Dominance*
I10: CW1* | J10: CW2* | K10: total height* | L10: Uncompacted Crown Length | M10: Compacted Crown Length
A11: 8 | B11: 8.1 | C11: 9(4) | D11: 10(3) | E11: 11(1) | F11: 12(1) | G11: 13(1) | H11: 14(1) | I11: 15(2) | J11: 16(2) | K11: 17(2) | L11: 18(2) | M11: 19(2) | N11: 20(1) | O11: 21(1) | P11: 22(2) | Q11: 23(2) | R11: 24(2) | S11: 25(1)
A12: 1 | B12: Xylia xylocarpa | D12: 31 | I12: 3 | J12: 3.5 | K12: =L12+M12+R12 -> 5.5 | L12: 3 | M12: 1 | R12: 1.5
A13: 2 | B13: Maddalasu | D13: 55 | I13: 3 | J13: 3.5 | K13: =L13+M13+R13 -> 6.8 | L13: 3 | M13: 2.5 | R13: 1.3
A14: 3 | B14: Aporosa lindleyana | D14: 34 | I14: 3 | J14: 2 | K14: =L14+M14+R14 -> 7 | L14: 4 | M14: 2.5 | R14: 0.5
A15: 4 | B15: Aporosa lindleyana | D15: 33 | I15: 4 | J15: 3.5 | K15: =L15+M15+R15 -> 7 | L15: 2.5 | M15: 4 | R15: 0.5
A16: 5 | B16: Macaranga peltata | D16: 100 | I16: 6 | J16: 3.7 | K16: =L16+M16+R16 -> 10.5 | L16: 2.5 | M16: 4 | R16: 4
A17: 6 | B17: Macaranga peltata | D17: 74 | I17: 5 | J17: 4 | K17: =L17+M17+R17 -> 7 | L17: 3 | M17: 2 | R17: 2

Sheet Form No.04
A1: Field Form No.4
A3: BAMBOO CLUMP ANALYSIS FORM
D5: Job No. | F5: From Code | H5: Mapsheet No. | J5: Grid ccode | S5: Average culm height (in dcm) | Y5: Bamboo quality
D6: 1(3) | F6: 2(2) | H6: 3(6) | J6: 4(6) | S6: Upto 1 cm top dia | V6: Upto 3 cm top dia
F7: 5 | S7: 38(3) | V7: 39(3) | Y7: 40(1)
A10: Species | C10: Sub plot number and clump SI.No. | D10: Clump GBH(cm) | E10: Clump size class | F10: Green sound culm | O10: Green damaged culm | X10: Dry sound culms | AB10: Dry damaged culms | AF10: Decayed culms | AG10: Avrage column height (in mtr) | AH10: Total no.of culms
A11: Name | B11: Code | F11: Current years | G11: one to two years old | K11: Over two years old | O11: Current years | P11: one to two years old | T11: Over two years old
G12: 1<2 cm | H12: 2<5cm | I12: 5<8 cm | J12: 8+cm | K12: 1<2 cm | L12: 2<5cm | M12: 5<8 cm | N12: 8+cm | P12: 1<2 cm | Q12: 2<5cm | R12: 5<8 cm | S12: 8+cm | T12: 1<2 cm | U12: 2<5cm | V12: 5<8 cm | W12: 8+cm | X12: 1<2 cm | Y12: 2<5cm | Z12: 5<8 cm | AA12: 8+cm | AB12: 1<2 cm | AC12: 2<5cm | AD12: 5<8 cm | AE12: 8+cm
A13: 5 | B13: 6(4) | C13: 7(3) | D13: 8(3) | E13: 9(1) | F13: 10(2) | G13: 11(2) | H13: 12(2) | I13: 13(2) | J13: 14(2) | K13: 15(2) | L13: 16(2) | M13: 17(2) | N13: 18(2) | O13: 19(2) | P13: 20(2) | Q13: 21(2) | R13: 22(2) | S13: 23(2) | T13: 24(2) | U13: 25(2) | V13: 26(2) | W13: 27(2) | X13: 28(2) | Y13: 29(2) | Z13: 30(2) | AA13: 31(2) | AB13: 32(2) | AC13: 33(2) | AD13: 34(2) | AE13: 35(2) | AF13: 36(2) | AH13: 37(3)

Sheet F-B
A1: PLOT ENUMERATION FORM – B (3m X 3m Plot) Grid No:
B2: Grid No: | F2: NORTH EAST CORNER
A3: Sl. No | B3: Species name | C3: Local name | D3: Collar Dia In cm (if any) | E3: Height (in m) | F3: NTFP utility | H3: Remarks, if any, about the condition of shrub vegetation
F4: Part of the plant body | G4: Approx. weight and or no.
A5: 1 | B5: Aporosa lindleyana | C5: Salle | D5: 2.5 | E5: 2 | F5: seeds | G5: =D5*E5 -> 5
A6: 2 | B6: Xylia xylocarpa | C6: Jambe | D6: 3.5 | E6: 1.5 | F6: seeds | G6: =D6*E6 -> 5.25
A7: 3 | B7: Macaranga peltata | C7: Battala Chandalike | D7: 3 | E7: 2 | F7: Edible fruits, Fiber | G7: =D7*E7 -> 6
A8: 4
A9: 5
A10: 6
A11: 7
A12: 8
A13: 9
A14: 10
A15: 11
A16: 12
A17: 13
A18: 14
A19: 15
... A26: 22
A28: OBSERVATIONS RECORDED
A29: 1 | B29: Wieght of humas & Soil carbon, Forest floor of 1m X 1m plot ( within the main plot) | H29: 0
A30: 2 | B30: Weight of All Woody litter i.e., all branches below 5cm Dia in 3m X 3m Plot | H30: 430g
A31: 3 | B31: Weight of All dead wood above 5cm Dia in 5m X 5m Plot | H31: 0
A32: 4 | B32: Weight of the all hurbs / grasses including Leaf litter in 1X1 Sub Plot | H32: 280g
A33: 5 | B33: Uprooted weight of Shrubs and climbers in gm/Kg (3m X 3m) | H33: 6Kg
B35: =B2 -> Grid No: | F35: SOUTH WEST CORNER
A36: Sl. No | B36: Species name | C36: Local name | D36: Collar Dia In cm (if any) | E36: Height (in m) | F36: NTFP utility | H36: Remarks, if any, about the condition of shrub vegetation
F37: Part of the plant body | G37: Approx. weight and or no.
A38: 1 | B38: Macaranga peltata | C38: Battala Chandalike | D38: 2.5 | E38: 2 | F38: Edible fruits, Fiber | G38: =D38*E38 -> 5
A39: 2 | B39: Macaranga peltata | C39: Battala Chandalike | D39: 2.2 | E39: 2 | G39: =D39*E39 -> 4.4
A40: 3 | B40: Leea indica | C40: Nertige | D40: 3 | E40: 3 | F40: Fruits, Fiber | G40: =D40*E40 -> 9
A41: 4 | B41: Callicarpa tomentosa | C41: Pandavara batti | D41: 2.5 | E41: 1.5 | G41: =D41*E41 -> 3.75
A42: 5
A43: 6
A44: 7
A45: 8
A46: 9
A47: 10
A48: 11
...

Sheet Form C
A1: PLOT ENUMERATION FORM – C (1m X 1m Plot) Grid No:
E2: NORTH EAST CORNER
A3: Sl. No | B3: Species name | C3: Local name | D3: Height (in cm) | E3: NTFP utility | G3: Remarks, if any, about the condition of herbal vegetation
E4: Part of the plant | F4: Approx. weight
E5: body | F5: or no.
A6: 1 | B6: Cyclea peltata | C6: Aadeballi | D6: 40 | E6: Roots , seeds | F6: =0.05*(D6)*(D6) -> 80
A7: 2 | B7: Arundinella sp | D7: 52 | F7: =0.05*(D7)*(D7) -> 135.2
A8: 3 | B8: Arundinella sp | D8: 40 | F8: =0.05*(D8)*(D8) -> 80
A9: 4 | B9: Arundinella sp | D9: 40 | F9: =0.05*(D9)*(D9) -> 80
A10: 5 | B10: Xylia xylocarpa | C10: Jambe | D10: 30 | E10: seeds | F10: =0.05*(D10)*(D10) -> 45
A11: 6
A12: 7
A13: 8
A14: 9
A15: 10
A16: 11
A17: 12
A18: 13
A19: 14
A20: 15
A21: 16
A22: 17
... A32: 27
A33: OBSERVATIONS RECORDED
B35: Grid No: | E35: SOUTH WEST CORNER
A36: Sl. No | B36: Species name | C36: Local name | D36: Height (in cm) | E36: NTFP utility | G36: Remarks, if any, about the condition of herbal vegetation
E37: Part of the plant | F37: Approx. weight
E38: body | F38: and or no.
A39: 1 | B39: Pothos scandens | C39: Apache Balli | D39: 30 | E39: Tubers and roots | F39: =0.05*(D39)*(D39) -> 45
A40: 2 | B40: Smilax spinosa | D40: 25 | E40: Tubers | F40: =0.05*(D40)*(D40) -> 31.25
A41: 3 | B41: Mussaenda frondosa | C41: Bellatte | D41: 60 | E41: Edible fruits, Fiber | F41: =0.05*(D41)*(D41) -> 180
A42: 4
A43: 5
A44: 6
A45: 7
A46: 8
A47: 9
A48: 10
A49: 11
A50: 12
...

Sheet Form 8
A1: Field Form No.8(Optional)
A3: STUMP, DEAD WOOD AND WOODY LITTER FORM
A5: Job No. | B5: form Code | C5: Mapsheet No* | D5: grid code* | E5: Lat* | F5: Long* | G5: Presence of Dead wood inforamtion* | I5: Stump and dead Wood: Circular Plot of size 2.8 m radius
A6: 1(3) | B6: 2(2) | C6: 3(6) | D6: 4(6) | E6: 5(6) | F6: 6(8) | G6: 17(10)
B7: 10 | I7: Woody litter: Circular plot of size 1.7 m radius
A9: Sub -plot number* | B9: Stump Information* | F9: Dead wood information*
B10: Species name | C10: Satus of stump(alive/dead) | D10: GBH in.cm | E10: Height in cm. | F10: Species code | G10: DBH/Dia(cm) | H10: length of the log (cm)
A11: 7(1) | B11: 8(4) | C11: 9(1) | D11: 10(3) | E11: 11(3) | F11: 12(4) | G11: 13(3) | H11: 14(3)

Sheet Sheet1
A1: NTFP/Medicinal plants information
A2: Si No | B2: Plant Species | C2: Habit | D2: Parts used | E2: Aprox qty/No
A3: 1
A4: 2
A5: 3
A6: 4
A7: 5
A8: 6
A9: 7
A10: 8
A11: 9
A12: 10
A13: 11
A14: 12
... A17: 15
A19: lichens Information
A20: Si No | B20: Species | C20: Host Plant | D20: No of branches in which present | E20: Remarks
A21: 1
A22: 2
A23: 3
A24: 4
A25: 5
A26: 6
A27: 7
