Workbook

Sheet Form-1
B1: Form I
B2: PLOT APPROACH FORM
A3: Name of Division : Sagara | C3: ( / / )
A5: Sl. No | B5: Heading | C5: Description
A6: 1 | B6: Range/ªÀ®AiÀÄ | C6: Subramanya
A7: 2 | B7: Block and/or beat | C7: Kilarmale RF (XII) / Madappady Beat
A8: 3 | B8: Compartment | C8: Xll-23
A9: 4 | B9: Grid / Væqï ¸ÀASÉå | C9: 647
A10: 5 | B10: LATITUDE(dd.dddd) | C10: 12.571630°
A11: 6 | B11: LONGITUDE (dd.dddd) | C11: 75.567956°
A12: 7 | B12: Journey/approach to the plot | C12: Starting from Aranthodu traverse by Sullia-Madikeri high road leading towards Goonadka for 1.45 Kms to reach Arladka.Here turn left and traverse by Asphalt road leading to Elimale for abut 10.00 Kms to reach Sevaje.Here turn right and traverse by Asphalt road for about 4.80 Kms to reach Madappady.Here turn right and travesre by Asphalt road and Mud road as well leading to Elive for about 3.40 Kms to reach a location with GPS Co-ordinates 12.573087°N, 75.565284°E.Here turn right and traverse SouthEast wards by foot for about 400 mts to reach the centre of the Plot
A13: 8 | B13: Ocular stock assessment | C13: Char, Kiral bhogi ,Ram pathre ,Ame vaate, Neervate,Hebbidiru,
A14: 9 | B14: General observational information
B15: (1)Tract - | C15: Hilly
B16: (2) Aspect - North/South/East/ West/North-East/South-East /North-West/South-west | C16: Western Aspect
B17: (3) Canopy Density - % ( >0.75 / 0.5-0.75 / <0.5) | C17: 0.75
B18: (4) Rock- | C18: Igneous rock, Sedimentory rocks
B19: (5) Soil- | C19: Red Sandy loam
B20: (6) Grasses- | C20: Hambuhullu
B21: (7) weeds- | C21: Madambadi /Datle (Psychotria sps )
B22: (8) Bamboos - | C22: Bambus bambos present in moderate density
B23: (9) Herbs- | C23: Salle(Aporousa lindleyana ), Huraiga (Actinodaphne hookeri)
B24: (10) Shrubs - | C24: Dalchinni, Hedagalu,Netti,Maddarasa,Kendal,Hulisedru,Kadugere
B25: (10) Underwood Species- | C25: Madambadi /Datle (Psychotria sps ),Huraiga (Actinodaphne hookeri),Neervate,
B26: (11) Climbers- | C26: Kadumenasu, Navakatte,Agcheppu, Arike balli
B27: (12) Rattans - | C27: Nagabettha. Halbettha, Handi bettha present in Moderate density
B28: (13) NTFP yielding Sps - | C28: dalchinni ram pathre
A29: 10 | B29: Conspicuous features | C29: heavy vate dalchinni
A30: 11 | B30: Removal of fuel wood and fodder | C30: 25-30 Head loads / year
A31: 12 | B31: Refrence Tree Sl No | C31: 1
A32: 13 | B32: Distance of Grid Centre from reference tree | C32: 1 mtr

Sheet Form-2
A1: Form II
A2: PLOT DESCRIPTION FORM
A4: Name of Division: Sagara | C4: ( / / )
A6: S.No | B6: Description | C6: Remarks
A7: 1 | B7: Range | C7: ='Form-1'!C6 -> Subramanya
A8: 2 | B8: Block and or beat | C8: ='Form-1'!C7 -> Kilarmale RF (XII) / Madappady Beat
A9: 3 | B9: Compartment | C9: ='Form-1'!C8 -> Xll-23
A10: 4 | B10: Grid No. | C10: ='Form-1'!C9 -> 647
A11: 5 | B11: LATITUDE(dd.dddd) | C11: ='Form-1'!C10 -> 12.571630°
A12: 6 | B12: LONGITUDE (dd.dddd) | C12: ='Form-1'!C11 -> 75.567956°
A13: 7 | B13: ALTTTUDE | C13: 301 mts
A14: 8 | B14: Legal status - Reserve Forest / Protected Forest/ Un classed Forest /Private Forest/ Private Land | C14: reserve forest
A15: 9 | B15: Land Use - Closed Forest /Dense Forest /Open Forest / Bamboo Forest/Grass land/Forest Roads/Scrub Forest | C15: dense forest
A16: 10 | B16: General topography : (Flat / Gently rolling / Hilly /Very Hilly/ Ravines / Gullies | C16: guddadinda koodide
A17: 11 | B17: Slope(in degrees):Upto 3° /4°-15°/16°-40°/41° and Above) | C17: 4 to 15
A18: 12 | B18: Aspect - North/South/East/ West/North-East/South-East /North-West/South-west | C18: west
A19: 13 | B19: Rock and geology - Igneous Rocks / Sedimentary Rocks / Metamorphic Rocks | C19: ='Form-1'!C18 -> Igneous rock, Sedimentory rocks
A20: 14 | B20: Soil data
B21: (1) Soil Type | C21: ='Form-1'!C19 -> Red Sandy loam
B22: (2) Soil Permeability | C22: High
B23: (3) Soil Depth | C23: 90 cm
A24: 15 | B24: Soil erosion : Heavy / Moderate /Mild /No erosion | C24: Mild
A25: 16 | B25: Crop composition :
A26: 17 | B26: Regeneration status : Adequate/ Moderate/ Poor /Absent | C26: Adequate
A27: 18 | B27: Injury/ damage to crop, if any : Top drying /Insect attack/Fungal infection/Leaf defoliator / Lopping / Girdling / Scarring / Damage by natural calamities / Damage by Wild life / Damage by Fire / None | C27: None
A28: 19 | B28: Grazing incidence : Heavy / Moderate / Light / None | C28: None
A29: 20 | B29: Presence of bamboos : Present / Absent | C29: Absent
A30: 21 | B30: Presence of grasses : Very dense / Dense / Moderate / Scanty / Absent | C30: Absent
A31: 22 | B31: Presence of weeds : Very dense / Dense / Moderate / Scanty / Absent | C31: Dense
A32: 23 | B32: Plantation status : | C32: None
A33: 24 | B33: Presence Of Invasive Species : | C33: Navakatte balli. Humi balli,Balli kasaraka
A34: 25 | B34: water bodies : | C34: Hadikallu hole present on the west of the plot
A35: 26 | B35: Drivers of degradation & Biotic Influence :
B36: Heavily degrated/ Moderately degrated / Mildly degrated /Not degrated | C36: No activity and not degraded
A37: 27 | B37: Faunal sighting, if any | C37: No
A38: 28 | B38: Faunal traces of flagship species. | C38: Foot prints of Indian gaur present
A39: 29 | B39: Canopy Density - % | C39: 0.85

Sheet F-III A1
A1: Form III
A2: FORM – A1
A3: PLOT ENUMERATION (31.62mX 31.62m Central Plot/lateral plot)
A5: Compartment No: | C5: ='[1]Form II'!C10 -> XII-23 | E5: Block /Village: | J5: Beat:
A6: Range: | C6: ='[1]Form 1'!C6 -> Subramanya | E6: Division: | G6: ='[1]Form 1'!C3 -> Mangalore | J6: ALT: | K6: ='[1]Form II'!C14 -> 274 m
A7: LAT: | C7: ='[1]Form 1'!C10 -> 12.571659° | E7: LONG: | G7: ='[1]Form 1'!C11 -> 75.554147° | J7: Grid No: | K7: ='Form-1'!C9 -> 647
A9: Sl. No | B9: Species name | D9: Local name | E9: GBH (OB) (cm) | F9: GBH (OB) | G9: Height of selected dominant trees (m) | H9: NTFP utility | L9: Remarks, if any, about the tree condition
F10: in cm | H10: Part of the tree | J10: Approx. weight and or no.
A11: 1 | B11: Callophyllum tomentosum | D11: holegere | E11: 123 | G11: 123
A12: 2 | B12: Aporousa lindleyana | D12: salle | E12: 59 | G12: 59
A13: 3 | B13: Aporousa lindleyana | D13: salle | E13: 56 | G13: 56
A14: 4 | B14: Terminalia paniculata | D14: matthi | E14: 154 | G14: 154
A15: 5 | B15: Aporousa lindleyana | D15: salle | E15: 46 | G15: 46
A16: 6 | B16: Terminalia paniculata | D16: hunalu | E16: 73 | G16: 73
A17: 7 | B17: Hopea parviflora | D17: kiral bhogi | E17: 360 | G17: 360
A18: 8 | B18: Lophopetalum whitianum | D18: balupale | E18: 172 | G18: 172
A19: 9 | B19: Myristica attenuata | D19: hedagalu | E19: 44 | G19: 44
A20: 10 | B20: Lophopetalum whitianum | D20: huriakki | E20: 65 | G20: 65
A21: 11 | B21: Hopea parviflora | D21: kiral bhogi | E21: 223 | G21: 223
A22: 12 | B22: Actinodaphne hookeri | D22: netti | E22: 36 | G22: 36
... A31: 21 | B31: Actinodaphne hookeri | D31: hurag, nitti | E31: 47 | G31: 47

Sheet FIII A2 (2)
A1: FORM-A2
A2: BAMBOO CLUMP ENUMERATION (31.62mX 31.62m Plot)
A5: Sl. No | B5: Species name | C5: Local Name | D5: Clump dia in cm | E5: Green sound culms | N5: Green damaged/ twisted | O5: Dry culms | Q5: Remarks, if any, about the clump condition
E6: Current | H6: One to | K6: Over two | O6: Sound | P6: Damaged/ twisted
E7: years | H7: two years | K7: years
E8: a | F8: b | G8: c | H8: a | I8: b | J8: c | K8: a | L8: b | M8: c
A9: Nil

Sheet F-B
A1: PLOT ENUMERATION FORM – B (3m X 3m Plot)
B2: Grid No: | C2: ='Form-1'!C9 -> 647 | F2: NORTH EAST CORNER
A3: Sl. No | B3: Species name | C3: Local name | D3: Collar Dia In mm (if any) | E3: Height (in m) | F3: NTFP utility | H3: Remarks, if any, about the condition of shrub vegetation
F4: Part of the plant body | G4: Approx. weight and or no.
A5: 1 | B5: Psychotria sps | C5: madambadi | D5: 13 | E5: 1
A6: 2 | B6: Psychotria sps | C6: madambadi | D6: 5 | E6: 0.8
A7: 3 | B7: Psychotria sps | C7: madambadi | D7: 9 | E7: 1
B9: =B2 -> Grid No: | C9: ='Form-2'!C10 -> 647 | F9: SOUTH WEST CORNER
A10: Sl. No | B10: Species name | C10: Local name | D10: Collar Dia In cm (if any) | E10: Height (in m) | F10: NTFP utility | H10: Remarks, if any, about the condition of shrub vegetation
F11: Part of the plant body | G11: Approx. weight and or no.
A12: 1 | B12: Calamus | C12: halbettha | D12: 1.9 | E12: 1
A13: 2 | B13: Psychotria sps | C13: madambadi | D13: 0.7 | E13: 1
A14: 3 | B14: Myristica attenuata | C14: hedagalu | D14: 2.8 | E14: 3
A15: 4 | B15: Psychotria sps | C15: madambadi | D15: 0.4 | E15: 0.8
A16: 5 | B16: Hopea parviflora | C16: bhogi | D16: 0.4 | E16: 1
B18: =B2 -> Grid No: | C18: ='Form-1'!C9 -> 647 | F18: SOUTH EAST CORNER
A19: Sl. No | B19: Species name | C19: Local name | D19: Collar Dia In cm (if any) | E19: Height (in m) | F19: NTFP utility | H19: Remarks, if any, about the condition of shrub vegetation
F20: Part of the plant body | G20: Approx. weight and or no.
A21: 1 | B21: Psychotria sps | C21: madambadi | D21: 1.1 | E21: 1
A22: 2 | C22: humi balli | D22: 1.9 | E22: 2
A23: 3 | B23: Hopea parviflora | C23: bhogi | D23: 2 | E23: 2
A24: 4 | B24: Psychotria sps | C24: madmbadi | D24: 1 | E24: 1
B26: =B2 -> Grid No: | C26: ='Form-1'!C9 -> 647 | F26: NORTH WEST CORNER
A27: Sl. No | B27: Species name | C27: Local name | D27: Collar Dia In cm (if any) | E27: Height (in m) | F27: NTFP utility | H27: Remarks, if any, about the condition of shrub vegetation
F28: Part of the plant body | G28: Approx. weight and or no.
A29: 1 | B29: Psychotria sps | C29: madmbadi | D29: 0.3 | E29: 0.5
A30: 2 | B30: Flacourtia montana | C30: sampige | D30: 0.1 | E30: 0.3
A31: 3 | B31: Hopea parviflora | C31: bhogi | D31: 4.4 | E31: 3
A32: 4 | B32: Hopea parviflora | C32: bhogi | D32: 2.4 | E32: 2
A33: 5 | B33: Piper nigrum | C33: kadumenasu | D33: 0.2 | E33: 0.3
A34: 6 | B34: Syzygium cumini | C34: neralu | D34: 0.1 | E34: 0.2
A35: 7 | B35: Hopea parviflora | C35: bhogi | D35: 2.3 | E35: 3

Sheet Form C
A1: PLOT ENUMERATION FORM – C (1m X 1m Plot) Grid No: | F1: ='Form-1'!C9 -> 647
E2: NORTH EAST CORNER
A3: Sl. No | B3: Species name | C3: Local name | D3: Height (in cm) | E3: NTFP utility | G3: Remarks, if any, about the condition of herbal vegetation
E4: Part of the plant body | F4: Approx. weight or Nos.
A5: 1 | B5: Psychotria sps | C5: madambadi | D5: 70 | F5: 30gm
A6: 2 | B6: Schleichera oleosa | C6: kendal | D6: 30 | F6: 15gm
A8: OBSERVATIONS RECORDED
A9: 1 | B9: Wieght of humas & Soil carbon, Forest floor of 1m X 1m plot ( within the main plot) | G9: 420gms
A10: 2 | B10: Weight of All Woody litter i.e., all branches below 5cm Dia in 3m X 3m Plot | G10: 60kg
A11: 3 | B11: Weight of All dead wood above 5cm Dia in 5m X 5m Plot | G11: 60kg
A12: 4 | B12: Weight of the all hurbs / grasses including Leaf litter in 1X1 Sub Plot | G12: 20gm
A13: 5 | B13: Uprooted weight of Shrubs and climbers in gm/Kg (3m X 3m) | G13: 5 Kg
B14: Grid No: | C14: ='Form-1'!C9 -> 647 | E14: SOUTH WEST CORNER
A15: Sl. No | B15: Species name | C15: Local name | D15: Height (in cm) | E15: NTFP utility | G15: Remarks, if any, about the condition of herbal vegetation
E16: Part of the plant body | F16: Approx. weight and or no.
A17: 1 | B17: Hopea parviflora | C17: bhogi | D17: 30 | F17: 30gm
A18: 2 | B18: Aporousa lindleyana | C18: salle | D18: 10
A20: OBSERVATIONS RECORDED
A21: 1 | B21: Wieght of humas & Soil carbon, Forest floor of 1m X 1m plot ( within the main plot) | G21: 0.457 kg
A22: 2 | B22: Weight of All Woody litter i.e., all branches below 5cm Dia in 3m X 3m Plot | G22: 1.878 kg
A23: 3 | B23: Weight of All dead wood above 5cm Dia in 5m X 5m Plot | G23: 2.456 kg
A24: 4 | B24: Weight of the all hurbs / grasses including Leaf litter in 1X1 Sub Plot | G24: 0.30 Kg
A25: 5 | B25: Uprooted weight of Shrubs and climbers in gm/Kg (3m X 3m) | G25: 1.3kg

Sheet Form 8
A1: Field Form No.8(Optional)
A3: STUMP, DEAD WOOD AND WOODY LITTER FORM
A5: Job No. | B5: form Code | C5: Mapsheet No* | D5: grid code* | E5: Lat* | F5: Long* | G5: Presence of Dead wood inforamtion* | I5: Stump and dead Wood: Circular Plot of size 2.8 m radius
A6: 1(3) | B6: 2(2) | C6: 3(6) | D6: 4(6) | E6: 5(6) | F6: 6(8) | G6: 17(10)
D7: 644 | I7: Woody litter: Circular plot of size 1.7 m radius
A9: Sub-plot number* | B9: Stump Information* | F9: Dead wood information*
B10: Species code | C10: Satus of stump (alive/dead) | D10: Dia (in.cm) | E10: Height (in cm.) | F10: Species code | G10: DBH/Dia (cm) | I10: length of the log (cm)
A11: 7(1) | B11: 8(4) | C11: 9(1) | D11: 10(3) | E11: 11(3) | F11: 12(4) | G11: 13(3) | I11: 14(3)
F12: beete | G12: 46 | I12: 500
F13: beete | G13: 56 | I13: 500
A18: Date:- | G18: Signature of the Crew
A19: Leader:-
A21: Note:-
A22: i) | B22: Firt Number in the row below the field headings represents the column number and the number inside the bracket represents the column width

Sheet NTFP-Med Plant
A1: NTFP/Medicinal plants information
A2: QgÀÄ CgÀtå GvÀà£ÀßUÀ¼À£ÀÄß ¤ÃqÀÄªÀ ¸À¸ÀåUÀ¼ÀÄ/ªÀÄgÀUÀ¼ÀÄ ºÁUÀÆ OµÀ¢üÃAiÀÄ ¸À¸ÀåUÀ¼ÀÄ
A3: Sl No | B3: Tree SPP | C3: Shrub | D3: hurb | E3: Climber | F3: Lichenes | G3: Parts used | H3: Aprox qty/No
A4: 1
A5: 2
A6: 3
A7: 4
A8: 5
A9: 6
A10: 7
A11: 8
A12: 9
A13: 10
A14: 11
A15: 12
... A25: 22

Sheet Canes
A1: Canes information
A2: ¨ÉvÀÛUÀ¼À §UÉÎ ªÀiÁ»w
A3: Sl.No. | B3: Cane Species Local Name | C3: Botanical Name | D3: Aproximate Nos
A4: 1
A5: 2
A6: 3
A7: 4
A8: 5
A9: 6
A10: 7
A11: 8
A12: 9
A13: 10
A14: 11
A15: 12
... A26: 23

Sheet SSN
C1: Sl No | D1: Local Name | E1: Botanical Name
D2: A
D3: Akkarkal | E3: Linociera malabarica
D4: Akkballi | E4: Pothos scandens
D5: Anangi
D6: Andi | E6: Carallia brachiata
D7: Aramadla | E7: Zanthoxylum rhetusa
D8: Arshinagurige | E8: Garcinia morella
D9: Archati | E9: Memecylon sps
D10: B
D11: Banati | E11: Lophopetalum wightianum
D12: Barakanabalige
D13: Bharanige | E13: Vitex altissima
D14: BiliNushni | E14: Cinnamomum sulphuratum
D15: Bodajanga | E15: Dichapetalum gelonioides
D16: Bolhuraiga
D17: Byne | E17: Caryota urens
D18: C
D19: Chanakalu | E19: Macaranga peltata
D20: Chippilaballi
D21: Chevi | E21: Dracaena terniflora
D22: Chunga | E22: Symplocos cochinensis
D23: Chungbalale | E23: Elaeocarpus serratus
D24: D
D25: Datle | E25: Psychotria sps
D26: Dalchini | E26: Cinnamomum malabaricum
D27: Devadari | E27: Erythroxylon monogynum
D28: E
D29: Nelli | E29: Emblica officinalis
D30: G
D31: Garagatti | E31: Ficus asperrima
D32: Garige | E32: Garuga pinnata
D33: Godda | E33: Lanea Coramandalica
D34: Gorabale | E34: Ixora brachiata
D35: Gudubalu
D36: Gulmavu | E36: Machilus macrantha
D37: Guddedasavala | E37: Ixora malabarica
D38: Gurige | E38: Strobilanthus sps
D40: H
D41: Halasu | E41: Artocarpus integrifolia
...
